import sys
import traceback

from discord.ext import commands
from resources.utility import ERRORS


class CommandErrorHandler(commands.Cog):
    def __init__(self, bot):
        self.bot = bot

    @commands.Cog.listener()
    async def on_command_error(self, ctx, error):

        # Isso evita que quaisquer comandos com manipuladores locais sejam manipulados aqui em on_command_error.
        if hasattr(ctx.command, 'on_error'):
            return

        # Todos os eventos de erros ignorados, qualquer coisa ignorada retornar√° e impedir√° que algo aconte√ßa.
        if isinstance(error, commands.CommandNotFound) or isinstance(error, commands.UserInputError):
            return

        # Qualquer comando desabilitado retornar√° uma mensagem de aviso
        elif isinstance(error, commands.DisabledCommand):
            return await ctx.send(f'<:negate:520418505993093130>‚îÇ**{ctx.command}** ``foi desabilitado``')

        # Manipula√ß√£o de erros voltados para erro de checagem, aqui eu trato de maneira particular erros de Check
        # dentro dos comandos para fins pessoais, ignorando totalmente os padroes comuns.
        if isinstance(error, commands.CheckFailure):
            if error.__str__() == 'The check functions for command register guild failed.':
                return await ctx.send(f"<:negate:520418505993093130>‚îÇ``VOC√ä N√ÉO TEM PERMISS√ÉO PARA USAR ESSE "
                                      f"COMANDO!``")
            elif error.__str__() not in ERRORS:
                return await ctx.send(f"{error}")

        # aqui fa√ßo as verifica√ß√µes dos cooldowns dos comandos padroes
        # obs: existem comandos com cooldowns personalizados que nao entram nesse contexto
        if isinstance(error, commands.CommandOnCooldown):

            # exce√ß√£o criada para o desenvolvedores
            if ctx.author.id in self.bot.staff:
                return await ctx.reinvoke()

            return await ctx.send(f"<:negate:520418505993093130>‚îÇ**Aguarde**: `Voc√™ deve esperar` **{{:.2f}}** "
                                  f"`segundos` `para mandar outro comando!`".format(error.retry_after),
                                  delete_after=float("{:.2f}".format(error.retry_after)))

        # aqui quando um erro nao √© tratado eu registro sua ocorrencia para averiguar sua origem
        channel = self.bot.get_channel(530419409311760394)
        await channel.send(f"<:oc_status:519896814225457152>‚îÇ``Ocorreu um erro no comando:`` "
                           f"**{ctx.command}**, ``no servidor:`` **{ctx.guild}**, ``no canal:`` "
                           f"**{ctx.channel}** ``e o erro foi:`` **{error}**")

        # Permite verificar exce√ß√µes originais geradas e enviadas para CommandInvokeError.
        # Se nada for encontrado. Mantemos a exce√ß√£o passada para on_command_error.
        error = getattr(error, 'original', error)

        # Todos os outros erros n√£o retornados v√™m aqui ... E podemos mostrar o TraceBack padr√£o.
        # como nao quero print de comando esperando para ser usado, fa√ßo a exce√ß√£o
        if not isinstance(error, commands.CommandOnCooldown):
            # e como nao quero print de comando mal executado pelo usuario fa√ßo a outra exce√ß√£o
            if not isinstance(error, commands.CheckFailure):
                print(f"\033[1;31m( ‚ùå ) | error in command: \033[1;34m{ctx.command}\033[1;31m, in Guild: "
                      f"\033[1;34m{ctx.guild}\033[1;31m, in Channel: \033[1;34m{ctx.channel}\033[1;31m. "
                      f"With error:\n \033[1;35m{error}\33[m\n")
                # o print do traceback √© para ver os erros mais detalhadamente
                traceback.print_exception(type(error), error, error.__traceback__, file=sys.stderr)


def setup(bot):
    bot.add_cog(CommandErrorHandler(bot))
    print('\033[1;33m( üî∂ ) | O evento \033[1;34mON_COMMAND_ERROR\033[1;33m foi carregado com sucesso!\33[m')
